<?xml version="1.0"?>
<robot>
  <include filename="$(find velma_defs)/defs/camera.urdf.xacro" />
  <macro name="velma_head" params="parent *origin">
    <joint name="head_frame_joint" type="fixed">
      <insert_block name="origin" />
      <parent link="${parent}"/>
      <child link="head_frame"/>
    </joint>
    
    <link name="head_frame">
    
    </link>
    
    <!-- pan -->
    <joint name="head_pan_joint" type="revolute">
      <origin xyz="0 0 0" rpy="0 0 0"/>
      <axis xyz="0 0 1"/>
      <parent link="head_frame"/>
      <child link="head_pan_link"/>
      
      <limit effort="100" velocity="100"/>
    </joint>
    
    <link name="head_pan_link">
    
    </link>
    
    <!-- tilt -->
    <joint name="head_tilt_joint" type="revolute">
      <origin xyz="0 0 0.05" rpy="-1.57 0.0 0" />
      <axis xyz="0 0 1"/>
      <parent link="head_pan_link"/>
      <child link="head_tilt_link"/>
      <limit effort="100" velocity="100"/>
    </joint>
    
    <link name="head_tilt_link"/>
    
    <!-- sensors -->
    
    <head_camera parent="head_tilt_link" name="stereo_left">
      <origin xyz="0.074819 -0.19424 0.039144" rpy="1.572 -0.0046408 0.0147"/>
    </head_camera>
    
    <head_camera parent="stereo_left_link" name="stereo_right">
      <origin xyz="0.0 -0.09 0.0" rpy="0 0 0"/>
    </head_camera>
    
    <head_camera parent="stereo_left_link" name="kinect_left_rgb">
      <origin xyz="0.013309 -0.010124 -0.06841" rpy="1.5634 -0.022662 0.37293"/>
    </head_camera>
    
    <head_camera parent="kinect_left_rgb_link" name="kinect_left_ir">
      <origin xyz="0.0 0.03 0.0" rpy="0 0 0"/>
    </head_camera>
    
    <head_camera parent="stereo_left_link" name="kinect_right_rgb">
      <origin xyz="0.00045739 -0.071104 -0.074766" rpy="1.5892 -0.035955 -0.34978"/>
    </head_camera>
    
    <head_camera parent="kinect_right_rgb_link" name="kinect_right_ir">
      <origin xyz="0.0 0.03 0.0" rpy="0 0 0"/>
    </head_camera>
  </macro>
</robot>

