<?xml version="1.0"?>
<robot xmlns:controller="http://playerstage.sourceforge.net/gazebo/xmlschema/#controller"
                        xmlns:interface="http://playerstage.sourceforge.net/gazebo/xmlschema/#interface"
                        xmlns:sensor="http://playerstage.sourceforge.net/gazebo/xmlschema/#sensor"
                        xmlns:xacro="http://playerstage.sourceforge.net/gazebo/xmlschema/#interface">

  <xacro:include filename="$(find velma_description)/defs/camera.urdf.xacro" />

  <macro name="velma_head" params="parent *origin">
    <joint name="head_base_joint" type="fixed">
      <insert_block name="origin" />
      <parent link="${parent}"/>
      <child link="head_base"/>
    </joint>
    
    <link name="head_base">
       <visual>
        <origin xyz="0 0 0.0" rpy="0 0 0" />
        <geometry>
          <mesh filename="package://velma_description/meshes/head_base.STL" />
        </geometry>
        <material name="torso_gray">
          <color rgba="0.5 0.5 0.5 1"/>
        </material>
      </visual>
    </link>
    
    <joint name="head_pan_motor_joint" type="fixed">
      <origin xyz="0 0 0.025" rpy="0 0 0" />
      <parent link="head_base"/>
      <child link="head_pan_motor"/>
    </joint>
    
    <link name="head_pan_motor">
       <visual>
        <origin xyz="0 0 0" rpy="0 0 0" />
        <geometry>
          <mesh filename="package://velma_description/meshes/head_pan.STL" />
        </geometry>
        <material name="torso_gray">
          <color rgba="0.5 0.5 0.5 1"/>
        </material>
      </visual>
    </link>
    
    <!-- pan -->
    <joint name="head_pan_joint" type="revolute">
      <origin xyz="0 0 0.062" rpy="0 0 0"/>
      <axis xyz="0 0 1"/>
      <parent link="head_pan_motor"/>
      <child link="head_pan_link"/>
      
      <limit lower="-1.57" upper="1.57" effort="100" velocity="1.57"/>
    </joint>
    
    <link name="head_pan_link">
      <visual>
        <origin xyz="0 0 0" rpy="0 0 0" />
        <geometry>
          <mesh filename="package://velma_description/meshes/head_tilt.STL" />
        </geometry>
        <material name="torso_gray">
          <color rgba="0.5 0.5 0.5 1"/>
        </material>
      </visual>
    </link>
    
    <!-- tilt -->
    <joint name="head_tilt_joint" type="revolute">
      <origin xyz="0 0 0.048" rpy="1.57 0.0 0" />
      <axis xyz="0 0 -1"/>
      <parent link="head_pan_link"/>
      <child link="head_tilt_link"/>
      <limit lower="-1.57" upper="1.57" effort="100" velocity="100"/>
    </joint>
    
    <link name="head_tilt_link">
      <visual>
        <origin xyz="0 0 0.04219" rpy="0 0 0" />
        <geometry>
          <mesh filename="package://velma_description/meshes/head_top.STL" />
        </geometry>
        <material name="torso_gray">
          <color rgba="0.5 0.5 0.5 1"/>
        </material>
      </visual>
    </link>
    
    <!-- sensors -->
    
    <head_camera parent="head_tilt_link" name="stereo_left">
      <origin xyz="${cal_head_to_stereo_left_x} ${cal_head_to_stereo_left_y} ${cal_head_to_stereo_left_z}"
              rpy="${cal_head_to_stereo_left_roll} ${cal_head_to_stereo_left_pitch} ${cal_head_to_stereo_left_yaw}"/>
    </head_camera>
    
    <head_camera parent="stereo_left_link" name="stereo_right">
      <origin xyz="0.0 -0.09 0.0" rpy="0 0 0"/>
    </head_camera>
  </macro>
</robot>

