<?xml version="1.0"?>
<robot>
  <macro name="velma_torso" params="parent *origin">
  
    <joint name="torso_base_joint" type="fixed">
      <insert_block name="origin" />
      <parent link="${parent}"/>
      <child link="torso_base"/>
    </joint>
  
    <link name="torso_base">

      <visual>
        <origin xyz="0 0 0" rpy="0.0 0 0" />
        <geometry>
          <mesh filename="package://velma_description/meshes/torso_base.STL" />
        </geometry>
        <material name="torso_base">
          <color rgba="0.3 0.3 0.3 1"/>
        </material>
      </visual>

      <collision>
        <origin xyz="0 0 0" rpy="0 0 0"/>
        <geometry>
          <mesh filename="package://velma_description/meshes/collision/torso_base_collision.STL" />
        </geometry>
      </collision>

      <self_collision_checking>
        <origin xyz="-0.2 0.0 0.6" rpy="1.57075 0 0"/>
        <geometry>
          <capsule radius="0.20" length="0.9"/>
        </geometry>
      </self_collision_checking>

    </link>

    <joint name="torso_0_joint" type="revolute">
      <origin xyz="0 0 0.0" rpy="0 0 0"/>
      <axis xyz="0 0 1"/>
      <limit lower="-1.57" upper="1.57" effort="100" velocity="100"/>
      <parent link="torso_base"/>
      <child link="torso_link0"/>
    </joint>
  
    <link name="torso_link0">
      <visual>
        <origin xyz="0 0 0.219" rpy="0.0 0 0" />
        <geometry>
          <mesh filename="package://velma_description/meshes/base_asm.STL" />
        </geometry>
        <material name="torso_base">
          <color rgba="0.5 0.5 0.5 1"/>
        </material>
      </visual>
      
      <visual>
        <origin xyz="0 0.0 1.055" rpy="0 0 0.0" />
        <geometry>
          <mesh filename="package://velma_description/meshes/top_base_asm.STL" />
        </geometry>
        <material name="Orange"/>
      </visual>
      
      <collision>
        <origin xyz="-0.03338 0 0.519" rpy="0 0 0"/>
        <geometry>
          <box size="0.34 0.3 0.6"/>
        </geometry>
      </collision>

      <self_collision_checking>
        <origin xyz="0 0.0 0.8" rpy="0 0 0"/>
        <geometry>
          <capsule radius="0.20" length="1.0"/>
        </geometry>
      </self_collision_checking>
    </link>
  </macro>
</robot>
