<?xml version="1.0"?>
<robot xmlns:controller="http://playerstage.sourceforge.net/gazebo/xmlschema/#controller"
                        xmlns:interface="http://playerstage.sourceforge.net/gazebo/xmlschema/#interface"
                        xmlns:sensor="http://playerstage.sourceforge.net/gazebo/xmlschema/#sensor"
                        xmlns:xacro="http://www.ros.org/wiki/xacro">

  <xacro:macro name="velma_torso" params="*origin">

    <link name="world" />

    <joint name="torso_base_joint" type="fixed">
      <xacro:insert_block name="origin" />
      <parent link="world"/>
      <child link="torso_base"/>
    </joint>

    <link name="torso_base">
      <visual>
        <origin xyz="0 0 0.1" rpy="0.0 0 0" />
        <geometry>
          <mesh filename="package://velma_description/meshes/torso_base.STL" />
        </geometry>
        <material name="torso_base">
          <color rgba="0.3 0.3 0.3 1"/>
        </material>
      </visual>
<!--
      <collision>
        <origin xyz="0 0 0.1" rpy="0 0 0"/>
        <geometry>
          <mesh filename="package://velma_description/meshes/collision/torso_base_collision.STL" />
        </geometry>
      </collision>
-->
<!--
      <self_collision_checking>
        <origin xyz="-0.2 0.0 0.6" rpy="1.57075 0 0"/>
        <geometry>
          <capsule radius="0.20" length="0.9"/>
        </geometry>
      </self_collision_checking>
-->
      <inertial>
        <mass value="30.0"/>
        <origin rpy="0 0 0" xyz="0 -0.06 0.130"/>
        <inertia ixx="0.9" ixy="0" ixz="0" iyy="0.9" iyz="0" izz="1.35"/>
      </inertial>
    </link>

    <gazebo reference="torso_base">
      <turnGravityOff>false</turnGravityOff>
      <selfCollide>true</selfCollide>
    </gazebo>

    <joint name="torso_0_joint" type="revolute">
      <origin xyz="0 0 0.1" rpy="0 0 0"/>
      <axis xyz="0 0 1"/>
      <limit lower="-1.57" upper="1.57" effort="100" velocity="100"/>
      <parent link="torso_base"/>
      <child link="torso_link0"/>
      <dynamics damping="10.0"/>
    </joint>
  
    <link name="torso_link0">
<!--
      <visual>
        <origin xyz="0 0 0.219" rpy="0.0 0 0" />
        <geometry>
          <mesh filename="package://velma_description/meshes/base_asm.STL" />
        </geometry>
        <material name="torso_base">
          <color rgba="0.5 0.5 0.5 1"/>
        </material>
      </visual>

      <visual>
        <origin xyz="-0.01 0 0.93" rpy="0.0 0 0" />
        <geometry>
          <box size="0.28 0.24 0.32" />
        </geometry>
        <material name="torso_base">
          <color rgba="0.5 0.5 0.5 1"/>
        </material>
      </visual>
      
      <visual>
        <origin xyz="0 0.0 1.055" rpy="0 0 0.0" />
        <geometry>
          <mesh filename="package://velma_description/meshes/top_base_asm.STL" />
        </geometry>
        <material name="torso_asm">
          <color rgba="1.0 0.487 0 1.0"/>
        </material>
      </visual>
-->
      <visual>
        <origin xyz="0 0 0.52" rpy="0 0 0"/>
        <geometry>
          <mesh filename="package://velma_description/meshes/collision/torso0_collision.stl" />
        </geometry>
        <material name="torso_base">
          <color rgba="0.7 0.7 0.7 1"/>
        </material>
      </visual>

      <collision>
        <origin xyz="0 0 0.52" rpy="0 0 0"/>
        <geometry>
          <mesh filename="package://velma_description/meshes/collision/torso0_collision.stl" />
        </geometry>
      </collision>

      <self_collision_checking>
        <origin xyz="0 0.0 0.8" rpy="0 0 0"/>
        <geometry>
          <capsule radius="0.20" length="1.0"/>
        </geometry>
      </self_collision_checking>

      <self_collision_checking>
        <origin xyz="-0.1 0.0 0.45" rpy="0 0 0"/>
        <geometry>
          <capsule radius="0.18" length="0.4"/>
        </geometry>
      </self_collision_checking>

      <inertial>
        <mass value="30.0"/>
        <origin rpy="0 0 0" xyz="0 -0.06 0.130"/>
        <inertia ixx="3.175" ixy="0" ixz="0" iyy="3.175" iyz="0" izz="1.35"/>
      </inertial>
    </link>

    <gazebo reference="torso_link0">
      <turnGravityOff>false</turnGravityOff>
      <selfCollide>true</selfCollide>
    </gazebo>

  </xacro:macro>
</robot>
