<?xml version="1.0"?>
<robot xmlns:controller="http://playerstage.sourceforge.net/gazebo/xmlschema/#controller"
                        xmlns:interface="http://playerstage.sourceforge.net/gazebo/xmlschema/#interface"
                        xmlns:sensor="http://playerstage.sourceforge.net/gazebo/xmlschema/#sensor"
                        xmlns:xacro="http://www.ros.org/wiki/xacro">

  <xacro:arg name="collision_detector" default="fcl"/>
  <xacro:property name="collision_detector" value="$(arg collision_detector)"/>

  <xacro:macro name="velma_torso" params="*origin">

    <link name="world" />

    <joint name="torso_base_joint" type="fixed">
      <xacro:insert_block name="origin" />
      <parent link="world"/>
      <child link="torso_base"/>
    </joint>

    <link name="torso_base">
      <!--
      <visual>
        <origin xyz="0 0 0.1" rpy="0.0 0 0" />
        <geometry>
          <mesh filename="package://velma_description/meshes/torso_base.STL" />
        </geometry>
        <material name="torso_base">
          <color rgba="0.3 0.3 0.3 1"/>
        </material>
      </visual>
    -->

      <visual>
        <origin xyz="0 0 0.1" rpy="0 0 0"/>
        <geometry>
          <box size="0.7 0.8 0.2" />
        </geometry>
        <material name="torso_base">
          <color rgba="0.3 0.3 0.3 1"/>
        </material>
      </visual>

      <visual>
        <origin xyz="0 0 0.26" rpy="0 0 0"/>
        <geometry>
          <box size="0.4 0.4 0.12" />
        </geometry>
        <material name="torso_base">
          <color rgba="0.3 0.3 0.3 1"/>
        </material>
      </visual>

      <collision>
        <origin xyz="0 0 0.1" rpy="0 0 0"/>
        <geometry>
          <box size="0.7 0.8 0.2" />
        </geometry>
      </collision>

      <collision>
        <origin xyz="0 0 0.26" rpy="0 0 0"/>
        <geometry>
          <box size="0.4 0.4 0.12" />
        </geometry>
      </collision>

<!--
      <collision>
        <origin xyz="0 0 0.1" rpy="0 0 0"/>
        <geometry>
          <mesh filename="package://velma_description/meshes/collision/torso_base_collision.STL" />
        </geometry>
      </collision>
-->
<!--
      <self_collision_checking>
        <origin xyz="-0.2 0.0 0.6" rpy="1.57075 0 0"/>
        <geometry>
          <capsule radius="0.20" length="0.9"/>
        </geometry>
      </self_collision_checking>
-->
      <inertial>
        <mass value="30.0"/>
        <origin rpy="0 0 0" xyz="0 -0.06 0.130"/>
        <inertia ixx="0.9" ixy="0" ixz="0" iyy="0.9" iyz="0" izz="1.35"/>
      </inertial>
    </link>

    <gazebo reference="torso_base">
      <turnGravityOff>false</turnGravityOff>
      <selfCollide>true</selfCollide>
      <material>Gazebo/DarkGrey</material>
    </gazebo>

    <!--
      Changed joint origin from 0.1 to 0.03 (moved 7cm down) to make it similar to the real robot.
      head_base - real height: 1.34
      in urdf (with joint origin at 0.1): 1.41
    -->
    <joint name="torso_0_joint" type="revolute">
      <origin xyz="0 0 0.03" rpy="0 0 0"/>
      <axis xyz="0 0 1"/>
      <limit lower="-1.57" upper="1.57" effort="100" velocity="100"/>
      <parent link="torso_base"/>
      <child link="torso_link0"/>
      <dynamics damping="10.0"/>
    </joint>
  
    <link name="torso_link0">
      <visual>
        <origin xyz="0 0 0.52" rpy="0 0 0"/>
        <geometry>
          <mesh filename="package://velma_description/meshes/collision/torso0_collision.stl" />
        </geometry>
        <material name="torso_base">
          <color rgba="0.7 0.7 0.7 1"/>
        </material>
      </visual>

      <xacro:if value="${collision_detector == 'fcl'}">
        <collision>
          <origin xyz="0 0 0.52" rpy="0 0 0"/>
          <geometry>
            <mesh filename="package://velma_description/meshes/collision/torso0_collision.stl" />
          </geometry>
        </collision>
        <collision>
          <origin xyz="0.04 0 1.57" rpy="0 0 0"/>
          <geometry>
            <sphere radius="0.24"/>
          </geometry>
        </collision>
      </xacro:if>
      <xacro:if value="${collision_detector == 'dart'}">
        <collision>
          <origin xyz="0 0 0.968570022583" rpy="0 0 0"/>
          <geometry>
            <box size="0.30822044611 0.276354163885 0.45334654808"/>
          </geometry>
        </collision>
        <collision>
          <origin xyz="0 0 1.18425571918" rpy="${M_PI/4} 0 0"/>
          <geometry>
            <box size="0.316696882248 0.19 0.19"/>
          </geometry>
        </collision>
        <collision>
          <origin xyz="-0.0265109799802 0 0.505967736244" rpy="0 0 0"/>
          <geometry>
            <box size="0.353161275387 0.255815982819 0.5"/>
          </geometry>
        </collision>
      </xacro:if>
      <self_collision_checking>
        <origin xyz="0 0.0 0.8" rpy="0 0 0"/>
        <geometry>
          <capsule radius="0.20" length="1.0"/>
        </geometry>
      </self_collision_checking>

      <self_collision_checking>
        <origin xyz="-0.1 0.0 0.45" rpy="0 0 0"/>
        <geometry>
          <capsule radius="0.18" length="0.4"/>
        </geometry>
      </self_collision_checking>

      <inertial>
        <mass value="30.0"/>
        <origin rpy="0 0 0" xyz="0 -0.06 0.130"/>
        <inertia ixx="3.175" ixy="0" ixz="0" iyy="3.175" iyz="0" izz="1.35"/>
      </inertial>
    </link>

    <gazebo reference="torso_link0">
      <turnGravityOff>false</turnGravityOff>
      <selfCollide>true</selfCollide>
      <material>Gazebo/DarkGrey</material>
    </gazebo>


    <joint name="head_bounding_sphere_joint" type="fixed">
      <origin xyz="0 0 0.03" rpy="0 0 0"/>
      <parent link="torso_base"/>
      <child link="head_bounding_sphere"/>
    </joint>
  
    <link name="head_bounding_sphere">
      <collision>
        <origin xyz="0.04 0 1.57" rpy="0 0 0"/>
        <geometry>
          <sphere radius="0.24"/>
        </geometry>
      </collision>
      <self_collision_checking>
        <origin xyz="0.04 0 1.57" rpy="0 0 0"/>
        <geometry>
          <sphere radius="0.24"/>
        </geometry>
      </self_collision_checking>

      <inertial>
        <mass value="0.3"/>
        <origin rpy="0 0 0" xyz="0 -0.06 0.130"/>
        <inertia ixx="0.03175" ixy="0" ixz="0" iyy="0.03175" iyz="0" izz="0.0135"/>
      </inertial>
    </link>

    <gazebo reference="head_bounding_sphere">
      <turnGravityOff>false</turnGravityOff>
      <selfCollide>true</selfCollide>
      <material>Gazebo/DarkGrey</material>
    </gazebo>

  </xacro:macro>
</robot>
